404 Not Found: The requested URL was not found on the server. If you entered the URL manually please check your spelling and try again.
Traceback (most recent call last):
  File "/usr/local/lib/python3.10/dist-packages/flask/app.py", line 870, in full_dispatch_request
    rv = self.dispatch_request()
  File "/usr/local/lib/python3.10/dist-packages/flask/app.py", line 844, in dispatch_request
    self.raise_routing_exception(req)
  File "/usr/local/lib/python3.10/dist-packages/flask/app.py", line 453, in raise_routing_exception
    raise request.routing_exception  # type: ignore[misc]
  File "/usr/local/lib/python3.10/dist-packages/flask/ctx.py", line 362, in match_request
    result = self.url_adapter.match(return_rule=True)  # type: ignore
  File "/usr/local/lib/python3.10/dist-packages/werkzeug/routing/map.py", line 624, in match
    raise NotFound() from None
werkzeug.exceptions.NotFound: 404 Not Found: The requested URL was not found on the server. If you entered the URL manually please check your spelling and try again.
404 Not Found: The requested URL was not found on the server. If you entered the URL manually please check your spelling and try again.
Traceback (most recent call last):
  File "/usr/local/lib/python3.10/dist-packages/flask/app.py", line 870, in full_dispatch_request
    rv = self.dispatch_request()
  File "/usr/local/lib/python3.10/dist-packages/flask/app.py", line 844, in dispatch_request
    self.raise_routing_exception(req)
  File "/usr/local/lib/python3.10/dist-packages/flask/app.py", line 453, in raise_routing_exception
    raise request.routing_exception  # type: ignore[misc]
  File "/usr/local/lib/python3.10/dist-packages/flask/ctx.py", line 362, in match_request
    result = self.url_adapter.match(return_rule=True)  # type: ignore
  File "/usr/local/lib/python3.10/dist-packages/werkzeug/routing/map.py", line 624, in match
    raise NotFound() from None
werkzeug.exceptions.NotFound: 404 Not Found: The requested URL was not found on the server. If you entered the URL manually please check your spelling and try again.
404 Not Found: The requested URL was not found on the server. If you entered the URL manually please check your spelling and try again.
Traceback (most recent call last):
  File "/usr/local/lib/python3.10/dist-packages/flask/app.py", line 870, in full_dispatch_request
    rv = self.dispatch_request()
  File "/usr/local/lib/python3.10/dist-packages/flask/app.py", line 844, in dispatch_request
    self.raise_routing_exception(req)
  File "/usr/local/lib/python3.10/dist-packages/flask/app.py", line 453, in raise_routing_exception
    raise request.routing_exception  # type: ignore[misc]
  File "/usr/local/lib/python3.10/dist-packages/flask/ctx.py", line 362, in match_request
    result = self.url_adapter.match(return_rule=True)  # type: ignore
  File "/usr/local/lib/python3.10/dist-packages/werkzeug/routing/map.py", line 624, in match
    raise NotFound() from None
werkzeug.exceptions.NotFound: 404 Not Found: The requested URL was not found on the server. If you entered the URL manually please check your spelling and try again.
404 Not Found: The requested URL was not found on the server. If you entered the URL manually please check your spelling and try again.
Traceback (most recent call last):
  File "/usr/local/lib/python3.10/dist-packages/flask/app.py", line 870, in full_dispatch_request
    rv = self.dispatch_request()
  File "/usr/local/lib/python3.10/dist-packages/flask/app.py", line 844, in dispatch_request
    self.raise_routing_exception(req)
  File "/usr/local/lib/python3.10/dist-packages/flask/app.py", line 453, in raise_routing_exception
    raise request.routing_exception  # type: ignore[misc]
  File "/usr/local/lib/python3.10/dist-packages/flask/ctx.py", line 362, in match_request
    result = self.url_adapter.match(return_rule=True)  # type: ignore
  File "/usr/local/lib/python3.10/dist-packages/werkzeug/routing/map.py", line 624, in match
    raise NotFound() from None
werkzeug.exceptions.NotFound: 404 Not Found: The requested URL was not found on the server. If you entered the URL manually please check your spelling and try again.
404 Not Found: The requested URL was not found on the server. If you entered the URL manually please check your spelling and try again.
Traceback (most recent call last):
  File "/usr/local/lib/python3.10/dist-packages/flask/app.py", line 870, in full_dispatch_request
    rv = self.dispatch_request()
  File "/usr/local/lib/python3.10/dist-packages/flask/app.py", line 844, in dispatch_request
    self.raise_routing_exception(req)
  File "/usr/local/lib/python3.10/dist-packages/flask/app.py", line 453, in raise_routing_exception
    raise request.routing_exception  # type: ignore[misc]
  File "/usr/local/lib/python3.10/dist-packages/flask/ctx.py", line 362, in match_request
    result = self.url_adapter.match(return_rule=True)  # type: ignore
  File "/usr/local/lib/python3.10/dist-packages/werkzeug/routing/map.py", line 624, in match
    raise NotFound() from None
werkzeug.exceptions.NotFound: 404 Not Found: The requested URL was not found on the server. If you entered the URL manually please check your spelling and try again.
404 Not Found: The requested URL was not found on the server. If you entered the URL manually please check your spelling and try again.
Traceback (most recent call last):
  File "/usr/local/lib/python3.10/dist-packages/flask/app.py", line 870, in full_dispatch_request
    rv = self.dispatch_request()
  File "/usr/local/lib/python3.10/dist-packages/flask/app.py", line 844, in dispatch_request
    self.raise_routing_exception(req)
  File "/usr/local/lib/python3.10/dist-packages/flask/app.py", line 453, in raise_routing_exception
    raise request.routing_exception  # type: ignore[misc]
  File "/usr/local/lib/python3.10/dist-packages/flask/ctx.py", line 362, in match_request
    result = self.url_adapter.match(return_rule=True)  # type: ignore
  File "/usr/local/lib/python3.10/dist-packages/werkzeug/routing/map.py", line 624, in match
    raise NotFound() from None
werkzeug.exceptions.NotFound: 404 Not Found: The requested URL was not found on the server. If you entered the URL manually please check your spelling and try again.
404 Not Found: The requested URL was not found on the server. If you entered the URL manually please check your spelling and try again.
Traceback (most recent call last):
  File "/usr/local/lib/python3.10/dist-packages/flask/app.py", line 870, in full_dispatch_request
    rv = self.dispatch_request()
  File "/usr/local/lib/python3.10/dist-packages/flask/app.py", line 844, in dispatch_request
    self.raise_routing_exception(req)
  File "/usr/local/lib/python3.10/dist-packages/flask/app.py", line 453, in raise_routing_exception
    raise request.routing_exception  # type: ignore[misc]
  File "/usr/local/lib/python3.10/dist-packages/flask/ctx.py", line 362, in match_request
    result = self.url_adapter.match(return_rule=True)  # type: ignore
  File "/usr/local/lib/python3.10/dist-packages/werkzeug/routing/map.py", line 624, in match
    raise NotFound() from None
werkzeug.exceptions.NotFound: 404 Not Found: The requested URL was not found on the server. If you entered the URL manually please check your spelling and try again.
404 Not Found: The requested URL was not found on the server. If you entered the URL manually please check your spelling and try again.
Traceback (most recent call last):
  File "/usr/local/lib/python3.10/dist-packages/flask/app.py", line 870, in full_dispatch_request
    rv = self.dispatch_request()
  File "/usr/local/lib/python3.10/dist-packages/flask/app.py", line 844, in dispatch_request
    self.raise_routing_exception(req)
  File "/usr/local/lib/python3.10/dist-packages/flask/app.py", line 453, in raise_routing_exception
    raise request.routing_exception  # type: ignore[misc]
  File "/usr/local/lib/python3.10/dist-packages/flask/ctx.py", line 362, in match_request
    result = self.url_adapter.match(return_rule=True)  # type: ignore
  File "/usr/local/lib/python3.10/dist-packages/werkzeug/routing/map.py", line 624, in match
    raise NotFound() from None
werkzeug.exceptions.NotFound: 404 Not Found: The requested URL was not found on the server. If you entered the URL manually please check your spelling and try again.
404 Not Found: The requested URL was not found on the server. If you entered the URL manually please check your spelling and try again.
Traceback (most recent call last):
  File "/usr/local/lib/python3.10/dist-packages/flask/app.py", line 870, in full_dispatch_request
    rv = self.dispatch_request()
  File "/usr/local/lib/python3.10/dist-packages/flask/app.py", line 844, in dispatch_request
    self.raise_routing_exception(req)
  File "/usr/local/lib/python3.10/dist-packages/flask/app.py", line 453, in raise_routing_exception
    raise request.routing_exception  # type: ignore[misc]
  File "/usr/local/lib/python3.10/dist-packages/flask/ctx.py", line 362, in match_request
    result = self.url_adapter.match(return_rule=True)  # type: ignore
  File "/usr/local/lib/python3.10/dist-packages/werkzeug/routing/map.py", line 624, in match
    raise NotFound() from None
werkzeug.exceptions.NotFound: 404 Not Found: The requested URL was not found on the server. If you entered the URL manually please check your spelling and try again.
404 Not Found: The requested URL was not found on the server. If you entered the URL manually please check your spelling and try again.
Traceback (most recent call last):
  File "/usr/local/lib/python3.10/dist-packages/flask/app.py", line 870, in full_dispatch_request
    rv = self.dispatch_request()
  File "/usr/local/lib/python3.10/dist-packages/flask/app.py", line 844, in dispatch_request
    self.raise_routing_exception(req)
  File "/usr/local/lib/python3.10/dist-packages/flask/app.py", line 453, in raise_routing_exception
    raise request.routing_exception  # type: ignore[misc]
  File "/usr/local/lib/python3.10/dist-packages/flask/ctx.py", line 362, in match_request
    result = self.url_adapter.match(return_rule=True)  # type: ignore
  File "/usr/local/lib/python3.10/dist-packages/werkzeug/routing/map.py", line 624, in match
    raise NotFound() from None
werkzeug.exceptions.NotFound: 404 Not Found: The requested URL was not found on the server. If you entered the URL manually please check your spelling and try again.
404 Not Found: The requested URL was not found on the server. If you entered the URL manually please check your spelling and try again.
Traceback (most recent call last):
  File "/usr/local/lib/python3.10/dist-packages/flask/app.py", line 870, in full_dispatch_request
    rv = self.dispatch_request()
  File "/usr/local/lib/python3.10/dist-packages/flask/app.py", line 844, in dispatch_request
    self.raise_routing_exception(req)
  File "/usr/local/lib/python3.10/dist-packages/flask/app.py", line 453, in raise_routing_exception
    raise request.routing_exception  # type: ignore[misc]
  File "/usr/local/lib/python3.10/dist-packages/flask/ctx.py", line 362, in match_request
    result = self.url_adapter.match(return_rule=True)  # type: ignore
  File "/usr/local/lib/python3.10/dist-packages/werkzeug/routing/map.py", line 624, in match
    raise NotFound() from None
werkzeug.exceptions.NotFound: 404 Not Found: The requested URL was not found on the server. If you entered the URL manually please check your spelling and try again.
404 Not Found: The requested URL was not found on the server. If you entered the URL manually please check your spelling and try again.
Traceback (most recent call last):
  File "/usr/local/lib/python3.10/dist-packages/flask/app.py", line 870, in full_dispatch_request
    rv = self.dispatch_request()
  File "/usr/local/lib/python3.10/dist-packages/flask/app.py", line 844, in dispatch_request
    self.raise_routing_exception(req)
  File "/usr/local/lib/python3.10/dist-packages/flask/app.py", line 453, in raise_routing_exception
    raise request.routing_exception  # type: ignore[misc]
  File "/usr/local/lib/python3.10/dist-packages/flask/ctx.py", line 362, in match_request
    result = self.url_adapter.match(return_rule=True)  # type: ignore
  File "/usr/local/lib/python3.10/dist-packages/werkzeug/routing/map.py", line 624, in match
    raise NotFound() from None
werkzeug.exceptions.NotFound: 404 Not Found: The requested URL was not found on the server. If you entered the URL manually please check your spelling and try again.
404 Not Found: The requested URL was not found on the server. If you entered the URL manually please check your spelling and try again.
Traceback (most recent call last):
  File "/usr/local/lib/python3.10/dist-packages/flask/app.py", line 870, in full_dispatch_request
    rv = self.dispatch_request()
  File "/usr/local/lib/python3.10/dist-packages/flask/app.py", line 844, in dispatch_request
    self.raise_routing_exception(req)
  File "/usr/local/lib/python3.10/dist-packages/flask/app.py", line 453, in raise_routing_exception
    raise request.routing_exception  # type: ignore[misc]
  File "/usr/local/lib/python3.10/dist-packages/flask/ctx.py", line 362, in match_request
    result = self.url_adapter.match(return_rule=True)  # type: ignore
  File "/usr/local/lib/python3.10/dist-packages/werkzeug/routing/map.py", line 624, in match
    raise NotFound() from None
werkzeug.exceptions.NotFound: 404 Not Found: The requested URL was not found on the server. If you entered the URL manually please check your spelling and try again.
404 Not Found: The requested URL was not found on the server. If you entered the URL manually please check your spelling and try again.
Traceback (most recent call last):
  File "/usr/local/lib/python3.10/dist-packages/flask/app.py", line 870, in full_dispatch_request
    rv = self.dispatch_request()
  File "/usr/local/lib/python3.10/dist-packages/flask/app.py", line 844, in dispatch_request
    self.raise_routing_exception(req)
  File "/usr/local/lib/python3.10/dist-packages/flask/app.py", line 453, in raise_routing_exception
    raise request.routing_exception  # type: ignore[misc]
  File "/usr/local/lib/python3.10/dist-packages/flask/ctx.py", line 362, in match_request
    result = self.url_adapter.match(return_rule=True)  # type: ignore
  File "/usr/local/lib/python3.10/dist-packages/werkzeug/routing/map.py", line 624, in match
    raise NotFound() from None
werkzeug.exceptions.NotFound: 404 Not Found: The requested URL was not found on the server. If you entered the URL manually please check your spelling and try again.
404 Not Found: The requested URL was not found on the server. If you entered the URL manually please check your spelling and try again.
Traceback (most recent call last):
  File "/usr/local/lib/python3.10/dist-packages/flask/app.py", line 870, in full_dispatch_request
    rv = self.dispatch_request()
  File "/usr/local/lib/python3.10/dist-packages/flask/app.py", line 844, in dispatch_request
    self.raise_routing_exception(req)
  File "/usr/local/lib/python3.10/dist-packages/flask/app.py", line 453, in raise_routing_exception
    raise request.routing_exception  # type: ignore[misc]
  File "/usr/local/lib/python3.10/dist-packages/flask/ctx.py", line 362, in match_request
    result = self.url_adapter.match(return_rule=True)  # type: ignore
  File "/usr/local/lib/python3.10/dist-packages/werkzeug/routing/map.py", line 624, in match
    raise NotFound() from None
werkzeug.exceptions.NotFound: 404 Not Found: The requested URL was not found on the server. If you entered the URL manually please check your spelling and try again.
404 Not Found: The requested URL was not found on the server. If you entered the URL manually please check your spelling and try again.
Traceback (most recent call last):
  File "/usr/local/lib/python3.10/dist-packages/flask/app.py", line 870, in full_dispatch_request
    rv = self.dispatch_request()
  File "/usr/local/lib/python3.10/dist-packages/flask/app.py", line 844, in dispatch_request
    self.raise_routing_exception(req)
  File "/usr/local/lib/python3.10/dist-packages/flask/app.py", line 453, in raise_routing_exception
    raise request.routing_exception  # type: ignore[misc]
  File "/usr/local/lib/python3.10/dist-packages/flask/ctx.py", line 362, in match_request
    result = self.url_adapter.match(return_rule=True)  # type: ignore
  File "/usr/local/lib/python3.10/dist-packages/werkzeug/routing/map.py", line 624, in match
    raise NotFound() from None
werkzeug.exceptions.NotFound: 404 Not Found: The requested URL was not found on the server. If you entered the URL manually please check your spelling and try again.
404 Not Found: The requested URL was not found on the server. If you entered the URL manually please check your spelling and try again.
Traceback (most recent call last):
  File "/usr/local/lib/python3.10/dist-packages/flask/app.py", line 870, in full_dispatch_request
    rv = self.dispatch_request()
  File "/usr/local/lib/python3.10/dist-packages/flask/app.py", line 844, in dispatch_request
    self.raise_routing_exception(req)
  File "/usr/local/lib/python3.10/dist-packages/flask/app.py", line 453, in raise_routing_exception
    raise request.routing_exception  # type: ignore[misc]
  File "/usr/local/lib/python3.10/dist-packages/flask/ctx.py", line 362, in match_request
    result = self.url_adapter.match(return_rule=True)  # type: ignore
  File "/usr/local/lib/python3.10/dist-packages/werkzeug/routing/map.py", line 624, in match
    raise NotFound() from None
werkzeug.exceptions.NotFound: 404 Not Found: The requested URL was not found on the server. If you entered the URL manually please check your spelling and try again.
404 Not Found: The requested URL was not found on the server. If you entered the URL manually please check your spelling and try again.
Traceback (most recent call last):
  File "/usr/local/lib/python3.10/dist-packages/flask/app.py", line 870, in full_dispatch_request
    rv = self.dispatch_request()
  File "/usr/local/lib/python3.10/dist-packages/flask/app.py", line 844, in dispatch_request
    self.raise_routing_exception(req)
  File "/usr/local/lib/python3.10/dist-packages/flask/app.py", line 453, in raise_routing_exception
    raise request.routing_exception  # type: ignore[misc]
  File "/usr/local/lib/python3.10/dist-packages/flask/ctx.py", line 362, in match_request
    result = self.url_adapter.match(return_rule=True)  # type: ignore
  File "/usr/local/lib/python3.10/dist-packages/werkzeug/routing/map.py", line 624, in match
    raise NotFound() from None
werkzeug.exceptions.NotFound: 404 Not Found: The requested URL was not found on the server. If you entered the URL manually please check your spelling and try again.
404 Not Found: The requested URL was not found on the server. If you entered the URL manually please check your spelling and try again.
Traceback (most recent call last):
  File "/usr/local/lib/python3.10/dist-packages/flask/app.py", line 870, in full_dispatch_request
    rv = self.dispatch_request()
  File "/usr/local/lib/python3.10/dist-packages/flask/app.py", line 844, in dispatch_request
    self.raise_routing_exception(req)
  File "/usr/local/lib/python3.10/dist-packages/flask/app.py", line 453, in raise_routing_exception
    raise request.routing_exception  # type: ignore[misc]
  File "/usr/local/lib/python3.10/dist-packages/flask/ctx.py", line 362, in match_request
    result = self.url_adapter.match(return_rule=True)  # type: ignore
  File "/usr/local/lib/python3.10/dist-packages/werkzeug/routing/map.py", line 624, in match
    raise NotFound() from None
werkzeug.exceptions.NotFound: 404 Not Found: The requested URL was not found on the server. If you entered the URL manually please check your spelling and try again.
404 Not Found: The requested URL was not found on the server. If you entered the URL manually please check your spelling and try again.
Traceback (most recent call last):
  File "/usr/local/lib/python3.10/dist-packages/flask/app.py", line 870, in full_dispatch_request
    rv = self.dispatch_request()
  File "/usr/local/lib/python3.10/dist-packages/flask/app.py", line 844, in dispatch_request
    self.raise_routing_exception(req)
  File "/usr/local/lib/python3.10/dist-packages/flask/app.py", line 453, in raise_routing_exception
    raise request.routing_exception  # type: ignore[misc]
  File "/usr/local/lib/python3.10/dist-packages/flask/ctx.py", line 362, in match_request
    result = self.url_adapter.match(return_rule=True)  # type: ignore
  File "/usr/local/lib/python3.10/dist-packages/werkzeug/routing/map.py", line 624, in match
    raise NotFound() from None
werkzeug.exceptions.NotFound: 404 Not Found: The requested URL was not found on the server. If you entered the URL manually please check your spelling and try again.
404 Not Found: The requested URL was not found on the server. If you entered the URL manually please check your spelling and try again.
Traceback (most recent call last):
  File "/usr/local/lib/python3.10/dist-packages/flask/app.py", line 870, in full_dispatch_request
    rv = self.dispatch_request()
  File "/usr/local/lib/python3.10/dist-packages/flask/app.py", line 844, in dispatch_request
    self.raise_routing_exception(req)
  File "/usr/local/lib/python3.10/dist-packages/flask/app.py", line 453, in raise_routing_exception
    raise request.routing_exception  # type: ignore[misc]
  File "/usr/local/lib/python3.10/dist-packages/flask/ctx.py", line 362, in match_request
    result = self.url_adapter.match(return_rule=True)  # type: ignore
  File "/usr/local/lib/python3.10/dist-packages/werkzeug/routing/map.py", line 624, in match
    raise NotFound() from None
werkzeug.exceptions.NotFound: 404 Not Found: The requested URL was not found on the server. If you entered the URL manually please check your spelling and try again.
404 Not Found: The requested URL was not found on the server. If you entered the URL manually please check your spelling and try again.
Traceback (most recent call last):
  File "/usr/local/lib/python3.10/dist-packages/flask/app.py", line 870, in full_dispatch_request
    rv = self.dispatch_request()
  File "/usr/local/lib/python3.10/dist-packages/flask/app.py", line 844, in dispatch_request
    self.raise_routing_exception(req)
  File "/usr/local/lib/python3.10/dist-packages/flask/app.py", line 453, in raise_routing_exception
    raise request.routing_exception  # type: ignore[misc]
  File "/usr/local/lib/python3.10/dist-packages/flask/ctx.py", line 362, in match_request
    result = self.url_adapter.match(return_rule=True)  # type: ignore
  File "/usr/local/lib/python3.10/dist-packages/werkzeug/routing/map.py", line 624, in match
    raise NotFound() from None
werkzeug.exceptions.NotFound: 404 Not Found: The requested URL was not found on the server. If you entered the URL manually please check your spelling and try again.
Account abnormal. Please ensure it's on good standing.
Account abnormal. Please ensure it's on good standing.
Traceback (most recent call last):
  File "/ragflow/rag/llm/embedding_model.py", line 153, in encode_queries
    return np.array(resp["output"]["embeddings"][0]
TypeError: 'NoneType' object is not subscriptable

During handling of the above exception, another exception occurred:

Traceback (most recent call last):
  File "/ragflow/api/apps/chunk_app.py", line 266, in retrieval_test
    ranks = retrievaler.retrieval(question, embd_mdl, kb.tenant_id, [kb_id], page, size,
  File "/ragflow/rag/nlp/search.py", line 349, in retrieval
    sres = self.search(req, index_name(tenant_id), embd_mdl)
  File "/ragflow/rag/nlp/search.py", line 113, in search
    s["knn"] = self._vector(
  File "/ragflow/rag/nlp/search.py", line 43, in _vector
    qv, c = emb_mdl.encode_queries(txt)
  File "/ragflow/rag/llm/embedding_model.py", line 156, in encode_queries
    raise Exception("Account abnormal. Please ensure it's on good standing.")
Exception: Account abnormal. Please ensure it's on good standing.
Account abnormal. Please ensure it's on good standing.
Traceback (most recent call last):
  File "/ragflow/rag/llm/embedding_model.py", line 153, in encode_queries
    return np.array(resp["output"]["embeddings"][0]
TypeError: 'NoneType' object is not subscriptable

During handling of the above exception, another exception occurred:

Traceback (most recent call last):
  File "/ragflow/api/apps/chunk_app.py", line 266, in retrieval_test
    ranks = retrievaler.retrieval(question, embd_mdl, kb.tenant_id, [kb_id], page, size,
  File "/ragflow/rag/nlp/search.py", line 349, in retrieval
    sres = self.search(req, index_name(tenant_id), embd_mdl)
  File "/ragflow/rag/nlp/search.py", line 113, in search
    s["knn"] = self._vector(
  File "/ragflow/rag/nlp/search.py", line 43, in _vector
    qv, c = emb_mdl.encode_queries(txt)
  File "/ragflow/rag/llm/embedding_model.py", line 156, in encode_queries
    raise Exception("Account abnormal. Please ensure it's on good standing.")
Exception: Account abnormal. Please ensure it's on good standing.
Fail put 8a79e48a37c311efa01b0242ac190006/歷代中醫珍本集成內科（3）_精校_直_B5_2.0.pdf: S3 operation failed; code: NoSuchBucket, message: The specified bucket does not exist, resource: /8a79e48a37c311efa01b0242ac190006, request_id: 17DE2282FA974B09, host_id: dd9025bab4ad464b049177c95eb6ebf374d3b3fd1af9251148b658df7ac2e3e8, bucket_name: 8a79e48a37c311efa01b0242ac190006
Account abnormal. Please ensure it's on good standing.
Account abnormal. Please ensure it's on good standing.
Account abnormal. Please ensure it's on good standing.
Account abnormal. Please ensure it's on good standing.
Account abnormal. Please ensure it's on good standing.
Account abnormal. Please ensure it's on good standing.
Account abnormal. Please ensure it's on good standing.
Account abnormal. Please ensure it's on good standing.
Account abnormal. Please ensure it's on good standing.
Account abnormal. Please ensure it's on good standing.
Account abnormal. Please ensure it's on good standing.
Account abnormal. Please ensure it's on good standing.
Account abnormal. Please ensure it's on good standing.
Account abnormal. Please ensure it's on good standing.
Account abnormal. Please ensure it's on good standing.
Account abnormal. Please ensure it's on good standing.
Account abnormal. Please ensure it's on good standing.
Account abnormal. Please ensure it's on good standing.
Account abnormal. Please ensure it's on good standing.
Account abnormal. Please ensure it's on good standing.
Account abnormal. Please ensure it's on good standing.
Account abnormal. Please ensure it's on good standing.
Account abnormal. Please ensure it's on good standing.
Account abnormal. Please ensure it's on good standing.
Account abnormal. Please ensure it's on good standing.
Traceback (most recent call last):
  File "/ragflow/rag/llm/embedding_model.py", line 153, in encode_queries
    return np.array(resp["output"]["embeddings"][0]
TypeError: 'NoneType' object is not subscriptable

During handling of the above exception, another exception occurred:

Traceback (most recent call last):
  File "/ragflow/api/apps/chunk_app.py", line 266, in retrieval_test
    ranks = retrievaler.retrieval(question, embd_mdl, kb.tenant_id, [kb_id], page, size,
  File "/ragflow/rag/nlp/search.py", line 349, in retrieval
    sres = self.search(req, index_name(tenant_id), embd_mdl)
  File "/ragflow/rag/nlp/search.py", line 113, in search
    s["knn"] = self._vector(
  File "/ragflow/rag/nlp/search.py", line 43, in _vector
    qv, c = emb_mdl.encode_queries(txt)
  File "/ragflow/rag/llm/embedding_model.py", line 156, in encode_queries
    raise Exception("Account abnormal. Please ensure it's on good standing.")
Exception: Account abnormal. Please ensure it's on good standing.
Account abnormal. Please ensure it's on good standing.
Traceback (most recent call last):
  File "/ragflow/rag/llm/embedding_model.py", line 153, in encode_queries
    return np.array(resp["output"]["embeddings"][0]
TypeError: 'NoneType' object is not subscriptable

During handling of the above exception, another exception occurred:

Traceback (most recent call last):
  File "/ragflow/api/apps/chunk_app.py", line 266, in retrieval_test
    ranks = retrievaler.retrieval(question, embd_mdl, kb.tenant_id, [kb_id], page, size,
  File "/ragflow/rag/nlp/search.py", line 349, in retrieval
    sres = self.search(req, index_name(tenant_id), embd_mdl)
  File "/ragflow/rag/nlp/search.py", line 113, in search
    s["knn"] = self._vector(
  File "/ragflow/rag/nlp/search.py", line 43, in _vector
    qv, c = emb_mdl.encode_queries(txt)
  File "/ragflow/rag/llm/embedding_model.py", line 156, in encode_queries
    raise Exception("Account abnormal. Please ensure it's on good standing.")
Exception: Account abnormal. Please ensure it's on good standing.
Account abnormal. Please ensure it's on good standing.
Traceback (most recent call last):
  File "/ragflow/rag/llm/embedding_model.py", line 153, in encode_queries
    return np.array(resp["output"]["embeddings"][0]
TypeError: 'NoneType' object is not subscriptable

During handling of the above exception, another exception occurred:

Traceback (most recent call last):
  File "/ragflow/api/apps/chunk_app.py", line 266, in retrieval_test
    ranks = retrievaler.retrieval(question, embd_mdl, kb.tenant_id, [kb_id], page, size,
  File "/ragflow/rag/nlp/search.py", line 349, in retrieval
    sres = self.search(req, index_name(tenant_id), embd_mdl)
  File "/ragflow/rag/nlp/search.py", line 113, in search
    s["knn"] = self._vector(
  File "/ragflow/rag/nlp/search.py", line 43, in _vector
    qv, c = emb_mdl.encode_queries(txt)
  File "/ragflow/rag/llm/embedding_model.py", line 156, in encode_queries
    raise Exception("Account abnormal. Please ensure it's on good standing.")
Exception: Account abnormal. Please ensure it's on good standing.
Account abnormal. Please ensure it's on good standing.
Traceback (most recent call last):
  File "/ragflow/rag/llm/embedding_model.py", line 153, in encode_queries
    return np.array(resp["output"]["embeddings"][0]
TypeError: 'NoneType' object is not subscriptable

During handling of the above exception, another exception occurred:

Traceback (most recent call last):
  File "/ragflow/api/apps/chunk_app.py", line 266, in retrieval_test
    ranks = retrievaler.retrieval(question, embd_mdl, kb.tenant_id, [kb_id], page, size,
  File "/ragflow/rag/nlp/search.py", line 349, in retrieval
    sres = self.search(req, index_name(tenant_id), embd_mdl)
  File "/ragflow/rag/nlp/search.py", line 113, in search
    s["knn"] = self._vector(
  File "/ragflow/rag/nlp/search.py", line 43, in _vector
    qv, c = emb_mdl.encode_queries(txt)
  File "/ragflow/rag/llm/embedding_model.py", line 156, in encode_queries
    raise Exception("Account abnormal. Please ensure it's on good standing.")
Exception: Account abnormal. Please ensure it's on good standing.
Fail put 8a79e48a37c311efa01b0242ac190006/歷代中醫珍本集成內科（3）_精校_直_B5_2.0.pdf: S3 operation failed; code: NoSuchKey, message: Object does not exist, resource: /8a79e48a37c311efa01b0242ac190006/%E6%AD%B7%E4%BB%A3%E4%B8%AD%E9%86%AB%E7%8F%8D%E6%9C%AC%E9%9B%86%E6%88%90%E5%85%A7%E7%A7%91%EF%BC%883%EF%BC%89_%E7%B2%BE%E6%A0%A1_%E7%9B%B4_B5_2.0.pdf, request_id: 17DE234F033D1B76, host_id: dd9025bab4ad464b049177c95eb6ebf374d3b3fd1af9251148b658df7ac2e3e8, bucket_name: 8a79e48a37c311efa01b0242ac190006, object_name: 歷代中醫珍本集成內科（3）_精校_直_B5_2.0.pdf
Fail put b6d438ea37ce11ef823d0242ac190006/歷代中醫珍本集成內科（3）_精校_直_B5_2.0.pdf: S3 operation failed; code: NoSuchBucket, message: The specified bucket does not exist, resource: /b6d438ea37ce11ef823d0242ac190006, request_id: 17DE26B714F52BD5, host_id: dd9025bab4ad464b049177c95eb6ebf374d3b3fd1af9251148b658df7ac2e3e8, bucket_name: b6d438ea37ce11ef823d0242ac190006
Account abnormal. Please ensure it's on good standing.
Fail put f24f491437ce11ef9a420242ac190006/歷代中醫珍本集成內科（3）_精校_直_B5_2.0.pdf: S3 operation failed; code: NoSuchBucket, message: The specified bucket does not exist, resource: /f24f491437ce11ef9a420242ac190006, request_id: 17DE273093C95DF1, host_id: dd9025bab4ad464b049177c95eb6ebf374d3b3fd1af9251148b658df7ac2e3e8, bucket_name: f24f491437ce11ef9a420242ac190006
Fail put f24f491437ce11ef9a420242ac190006/孔伯華醫集_精校_直_B5_2.0.pdf: S3 operation failed; code: NoSuchKey, message: Object does not exist, resource: /f24f491437ce11ef9a420242ac190006/%E5%AD%94%E4%BC%AF%E8%8F%AF%E9%86%AB%E9%9B%86_%E7%B2%BE%E6%A0%A1_%E7%9B%B4_B5_2.0.pdf, request_id: 17DE3F97DF4FD2CF, host_id: dd9025bab4ad464b049177c95eb6ebf374d3b3fd1af9251148b658df7ac2e3e8, bucket_name: f24f491437ce11ef9a420242ac190006, object_name: 孔伯華醫集_精校_直_B5_2.0.pdf
Fail put f24f491437ce11ef9a420242ac190006/中醫臨床知要_精校_直_B5_2.0.pdf: S3 operation failed; code: NoSuchKey, message: Object does not exist, resource: /f24f491437ce11ef9a420242ac190006/%E4%B8%AD%E9%86%AB%E8%87%A8%E5%BA%8A%E7%9F%A5%E8%A6%81_%E7%B2%BE%E6%A0%A1_%E7%9B%B4_B5_2.0.pdf, request_id: 17DE3F97F5EA38DB, host_id: dd9025bab4ad464b049177c95eb6ebf374d3b3fd1af9251148b658df7ac2e3e8, bucket_name: f24f491437ce11ef9a420242ac190006, object_name: 中醫臨床知要_精校_直_B5_2.0.pdf
Fail put f24f491437ce11ef9a420242ac190006/自學中醫之路叢書－病因病機學說_精校_直_B5_2.0.pdf: S3 operation failed; code: NoSuchKey, message: Object does not exist, resource: /f24f491437ce11ef9a420242ac190006/%E8%87%AA%E5%AD%B8%E4%B8%AD%E9%86%AB%E4%B9%8B%E8%B7%AF%E5%8F%A2%E6%9B%B8%EF%BC%8D%E7%97%85%E5%9B%A0%E7%97%85%E6%A9%9F%E5%AD%B8%E8%AA%AA_%E7%B2%BE%E6%A0%A1_%E7%9B%B4_B5_2.0.pdf, request_id: 17DE3F9808722D37, host_id: dd9025bab4ad464b049177c95eb6ebf374d3b3fd1af9251148b658df7ac2e3e8, bucket_name: f24f491437ce11ef9a420242ac190006, object_name: 自學中醫之路叢書－病因病機學說_精校_直_B5_2.0.pdf
Fail put f24f491437ce11ef9a420242ac190006/歷代中醫珍本集成醫案十_精校_直_B5_2.0.pdf: S3 operation failed; code: NoSuchKey, message: Object does not exist, resource: /f24f491437ce11ef9a420242ac190006/%E6%AD%B7%E4%BB%A3%E4%B8%AD%E9%86%AB%E7%8F%8D%E6%9C%AC%E9%9B%86%E6%88%90%E9%86%AB%E6%A1%88%E5%8D%81_%E7%B2%BE%E6%A0%A1_%E7%9B%B4_B5_2.0.pdf, request_id: 17DE3F980F9C68C5, host_id: dd9025bab4ad464b049177c95eb6ebf374d3b3fd1af9251148b658df7ac2e3e8, bucket_name: f24f491437ce11ef9a420242ac190006, object_name: 歷代中醫珍本集成醫案十_精校_直_B5_2.0.pdf
Fail put f24f491437ce11ef9a420242ac190006/歷代中醫珍本集成醫案（9）_精校_直_B5_2.0.pdf: S3 operation failed; code: NoSuchKey, message: Object does not exist, resource: /f24f491437ce11ef9a420242ac190006/%E6%AD%B7%E4%BB%A3%E4%B8%AD%E9%86%AB%E7%8F%8D%E6%9C%AC%E9%9B%86%E6%88%90%E9%86%AB%E6%A1%88%EF%BC%889%EF%BC%89_%E7%B2%BE%E6%A0%A1_%E7%9B%B4_B5_2.0.pdf, request_id: 17DE3F981A14E475, host_id: dd9025bab4ad464b049177c95eb6ebf374d3b3fd1af9251148b658df7ac2e3e8, bucket_name: f24f491437ce11ef9a420242ac190006, object_name: 歷代中醫珍本集成醫案（9）_精校_直_B5_2.0.pdf
Fail put f24f491437ce11ef9a420242ac190006/歷代中醫珍本集成醫案八_精校_直_B5_2.0.pdf: S3 operation failed; code: NoSuchKey, message: Object does not exist, resource: /f24f491437ce11ef9a420242ac190006/%E6%AD%B7%E4%BB%A3%E4%B8%AD%E9%86%AB%E7%8F%8D%E6%9C%AC%E9%9B%86%E6%88%90%E9%86%AB%E6%A1%88%E5%85%AB_%E7%B2%BE%E6%A0%A1_%E7%9B%B4_B5_2.0.pdf, request_id: 17DE3F9826544624, host_id: dd9025bab4ad464b049177c95eb6ebf374d3b3fd1af9251148b658df7ac2e3e8, bucket_name: f24f491437ce11ef9a420242ac190006, object_name: 歷代中醫珍本集成醫案八_精校_直_B5_2.0.pdf
Fail put f24f491437ce11ef9a420242ac190006/歷代中醫珍本集成醫案（6-7）_精校_直_B5_2.0.pdf: S3 operation failed; code: NoSuchKey, message: Object does not exist, resource: /f24f491437ce11ef9a420242ac190006/%E6%AD%B7%E4%BB%A3%E4%B8%AD%E9%86%AB%E7%8F%8D%E6%9C%AC%E9%9B%86%E6%88%90%E9%86%AB%E6%A1%88%EF%BC%886-7%EF%BC%89_%E7%B2%BE%E6%A0%A1_%E7%9B%B4_B5_2.0.pdf, request_id: 17DE3F982F031512, host_id: dd9025bab4ad464b049177c95eb6ebf374d3b3fd1af9251148b658df7ac2e3e8, bucket_name: f24f491437ce11ef9a420242ac190006, object_name: 歷代中醫珍本集成醫案（6-7）_精校_直_B5_2.0.pdf
Fail put f24f491437ce11ef9a420242ac190006/歷代中醫珍本集成醫案五_精校_直_B5_2.0.pdf: S3 operation failed; code: NoSuchKey, message: Object does not exist, resource: /f24f491437ce11ef9a420242ac190006/%E6%AD%B7%E4%BB%A3%E4%B8%AD%E9%86%AB%E7%8F%8D%E6%9C%AC%E9%9B%86%E6%88%90%E9%86%AB%E6%A1%88%E4%BA%94_%E7%B2%BE%E6%A0%A1_%E7%9B%B4_B5_2.0.pdf, request_id: 17DE3F983D2F020A, host_id: dd9025bab4ad464b049177c95eb6ebf374d3b3fd1af9251148b658df7ac2e3e8, bucket_name: f24f491437ce11ef9a420242ac190006, object_name: 歷代中醫珍本集成醫案五_精校_直_B5_2.0.pdf
Fail put f24f491437ce11ef9a420242ac190006/歷代中醫珍本集成內科（4）_精校_直_B5_2.0.pdf: S3 operation failed; code: NoSuchKey, message: Object does not exist, resource: /f24f491437ce11ef9a420242ac190006/%E6%AD%B7%E4%BB%A3%E4%B8%AD%E9%86%AB%E7%8F%8D%E6%9C%AC%E9%9B%86%E6%88%90%E5%85%A7%E7%A7%91%EF%BC%884%EF%BC%89_%E7%B2%BE%E6%A0%A1_%E7%9B%B4_B5_2.0.pdf, request_id: 17DE3F989F4D33B7, host_id: dd9025bab4ad464b049177c95eb6ebf374d3b3fd1af9251148b658df7ac2e3e8, bucket_name: f24f491437ce11ef9a420242ac190006, object_name: 歷代中醫珍本集成內科（4）_精校_直_B5_2.0.pdf
Fail put f24f491437ce11ef9a420242ac190006/歷代中醫珍本集成醫案（2）_精校_直_B5_2.0.pdf: S3 operation failed; code: NoSuchKey, message: Object does not exist, resource: /f24f491437ce11ef9a420242ac190006/%E6%AD%B7%E4%BB%A3%E4%B8%AD%E9%86%AB%E7%8F%8D%E6%9C%AC%E9%9B%86%E6%88%90%E9%86%AB%E6%A1%88%EF%BC%882%EF%BC%89_%E7%B2%BE%E6%A0%A1_%E7%9B%B4_B5_2.0.pdf, request_id: 17DE3F98A80BCF02, host_id: dd9025bab4ad464b049177c95eb6ebf374d3b3fd1af9251148b658df7ac2e3e8, bucket_name: f24f491437ce11ef9a420242ac190006, object_name: 歷代中醫珍本集成醫案（2）_精校_直_B5_2.0.pdf
Fail put f24f491437ce11ef9a420242ac190006/歷代中醫珍本集成醫案（1）_精校_直_B5_2.0.pdf: S3 operation failed; code: NoSuchKey, message: Object does not exist, resource: /f24f491437ce11ef9a420242ac190006/%E6%AD%B7%E4%BB%A3%E4%B8%AD%E9%86%AB%E7%8F%8D%E6%9C%AC%E9%9B%86%E6%88%90%E9%86%AB%E6%A1%88%EF%BC%881%EF%BC%89_%E7%B2%BE%E6%A0%A1_%E7%9B%B4_B5_2.0.pdf, request_id: 17DE3F98B095F32E, host_id: dd9025bab4ad464b049177c95eb6ebf374d3b3fd1af9251148b658df7ac2e3e8, bucket_name: f24f491437ce11ef9a420242ac190006, object_name: 歷代中醫珍本集成醫案（1）_精校_直_B5_2.0.pdf
failed to generate embedding
Fail to connect to es: Connection error caused by: ConnectionError(Connection error caused by: NewConnectionError(<urllib3.connection.HTTPConnection object at 0x7ffad5d0f0a0>: Failed to establish a new connection: [Errno 111] Connection refused))
Fail to connect to es: Connection error caused by: ConnectionError(Connection error caused by: NewConnectionError(<urllib3.connection.HTTPConnection object at 0x7f92f8c052a0>: Failed to establish a new connection: [Errno 111] Connection refused))
Fail to connect to es: Connection error caused by: ConnectionError(Connection error caused by: NewConnectionError(<urllib3.connection.HTTPConnection object at 0x7ffad5d6d090>: Failed to establish a new connection: [Errno 111] Connection refused))
Fail to connect to es: Connection error caused by: ConnectionError(Connection error caused by: NewConnectionError(<urllib3.connection.HTTPConnection object at 0x7f92f8c072b0>: Failed to establish a new connection: [Errno 111] Connection refused))
Fail to connect to es: Connection error caused by: ConnectionError(Connection error caused by: NewConnectionError(<urllib3.connection.HTTPConnection object at 0x7ffad5d6e710>: Failed to establish a new connection: [Errno 111] Connection refused))
Fail to connect to es: Connection error caused by: ConnectionError(Connection error caused by: NewConnectionError(<urllib3.connection.HTTPConnection object at 0x7f92f7e78910>: Failed to establish a new connection: [Errno 111] Connection refused))
Fail to connect to es: Connection error caused by: ConnectionError(Connection error caused by: NewConnectionError(<urllib3.connection.HTTPConnection object at 0x7ffad5d70370>: Failed to establish a new connection: [Errno 111] Connection refused))
Fail to connect to es: Connection error caused by: ConnectionError(Connection error caused by: NewConnectionError(<urllib3.connection.HTTPConnection object at 0x7f92f7e7a530>: Failed to establish a new connection: [Errno 111] Connection refused))
Fail to connect to es: Connection error caused by: ConnectionError(Connection error caused by: NewConnectionError(<urllib3.connection.HTTPConnection object at 0x7ffad5d71810>: Failed to establish a new connection: [Errno 111] Connection refused))
Fail to connect to es: Connection error caused by: ConnectionError(Connection error caused by: NewConnectionError(<urllib3.connection.HTTPConnection object at 0x7f92f7e7b9d0>: Failed to establish a new connection: [Errno 111] Connection refused))
Fail to connect to es: Connection error caused by: ConnectionError(Connection error caused by: NewConnectionError(<urllib3.connection.HTTPConnection object at 0x7ffad5d73610>: Failed to establish a new connection: [Errno 111] Connection refused))
Fail to connect to es: Connection error caused by: ConnectionError(Connection error caused by: NewConnectionError(<urllib3.connection.HTTPConnection object at 0x7f92f7e78e80>: Failed to establish a new connection: [Errno 111] Connection refused))
Fail to connect to es: Connection error caused by: ConnectionError(Connection error caused by: NewConnectionError(<urllib3.connection.HTTPConnection object at 0x7ffad5d70c10>: Failed to establish a new connection: [Errno 111] Connection refused))
Fail to connect to es: Connection error caused by: ConnectionError(Connection error caused by: NewConnectionError(<urllib3.connection.HTTPConnection object at 0x7f92f7e8d720>: Failed to establish a new connection: [Errno 111] Connection refused))
Fail to connect to es: Connection error caused by: ConnectionError(Connection error caused by: NewConnectionError(<urllib3.connection.HTTPConnection object at 0x7ffad5d948b0>: Failed to establish a new connection: [Errno 111] Connection refused))
Fail to connect to es: Connection error caused by: ConnectionError(Connection error caused by: NewConnectionError(<urllib3.connection.HTTPConnection object at 0x7f92f7e8ea70>: Failed to establish a new connection: [Errno 111] Connection refused))
Fail put f24f491437ce11ef9a420242ac190006/自學中醫之路叢書－病因病機學說_精校_直_B5_2.0.pdf: S3 operation failed; code: NoSuchKey, message: Object does not exist, resource: /f24f491437ce11ef9a420242ac190006/%E8%87%AA%E5%AD%B8%E4%B8%AD%E9%86%AB%E4%B9%8B%E8%B7%AF%E5%8F%A2%E6%9B%B8%EF%BC%8D%E7%97%85%E5%9B%A0%E7%97%85%E6%A9%9F%E5%AD%B8%E8%AA%AA_%E7%B2%BE%E6%A0%A1_%E7%9B%B4_B5_2.0.pdf, request_id: 17DE443BD5CE951D, host_id: dd9025bab4ad464b049177c95eb6ebf374d3b3fd1af9251148b658df7ac2e3e8, bucket_name: f24f491437ce11ef9a420242ac190006, object_name: 自學中醫之路叢書－病因病機學說_精校_直_B5_2.0.pdf
Fail to connect to es: Connection error caused by: ConnectionError(Connection error caused by: NewConnectionError(<urllib3.connection.HTTPConnection object at 0x7f90a91ed240>: Failed to establish a new connection: [Errno 111] Connection refused))
Fail to connect to es: Connection error caused by: ConnectionError(Connection error caused by: NewConnectionError(<urllib3.connection.HTTPConnection object at 0x7f5122fd6fe0>: Failed to establish a new connection: [Errno 111] Connection refused))
Fail to connect to es: Connection error caused by: ConnectionError(Connection error caused by: NewConnectionError(<urllib3.connection.HTTPConnection object at 0x7f90a91ef1f0>: Failed to establish a new connection: [Errno 111] Connection refused))
Fail to connect to es: Connection error caused by: ConnectionError(Connection error caused by: NewConnectionError(<urllib3.connection.HTTPConnection object at 0x7f512302cfd0>: Failed to establish a new connection: [Errno 111] Connection refused))
Fail to connect to es: Connection error caused by: ConnectionError(Connection error caused by: NewConnectionError(<urllib3.connection.HTTPConnection object at 0x7f90a92208b0>: Failed to establish a new connection: [Errno 111] Connection refused))
Fail to connect to es: Connection error caused by: ConnectionError(Connection error caused by: NewConnectionError(<urllib3.connection.HTTPConnection object at 0x7f512302e650>: Failed to establish a new connection: [Errno 111] Connection refused))
Fail to connect to es: Connection error caused by: ConnectionError(Connection error caused by: NewConnectionError(<urllib3.connection.HTTPConnection object at 0x7f512303c2b0>: Failed to establish a new connection: [Errno 111] Connection refused))
Fail to connect to es: Connection error caused by: ConnectionError(Connection error caused by: NewConnectionError(<urllib3.connection.HTTPConnection object at 0x7f90a92224d0>: Failed to establish a new connection: [Errno 111] Connection refused))
Fail to connect to es: Connection error caused by: ConnectionError(Connection error caused by: NewConnectionError(<urllib3.connection.HTTPConnection object at 0x7f512303d750>: Failed to establish a new connection: [Errno 111] Connection refused))
Fail to connect to es: Connection error caused by: ConnectionError(Connection error caused by: NewConnectionError(<urllib3.connection.HTTPConnection object at 0x7f90a9223970>: Failed to establish a new connection: [Errno 111] Connection refused))
Fail to connect to es: Connection error caused by: ConnectionError(Connection error caused by: NewConnectionError(<urllib3.connection.HTTPConnection object at 0x7f90a92357b0>: Failed to establish a new connection: [Errno 111] Connection refused))
Fail to connect to es: Connection error caused by: ConnectionError(Connection error caused by: NewConnectionError(<urllib3.connection.HTTPConnection object at 0x7f512303f550>: Failed to establish a new connection: [Errno 111] Connection refused))
Fail to connect to es: Connection error caused by: ConnectionError(Connection error caused by: NewConnectionError(<urllib3.connection.HTTPConnection object at 0x7f90a92356c0>: Failed to establish a new connection: [Errno 111] Connection refused))
Fail to connect to es: Connection error caused by: ConnectionError(Connection error caused by: NewConnectionError(<urllib3.connection.HTTPConnection object at 0x7f512303ca30>: Failed to establish a new connection: [Errno 111] Connection refused))
Fail to connect to es: Connection error caused by: ConnectionError(Connection error caused by: NewConnectionError(<urllib3.connection.HTTPConnection object at 0x7f90a9236c50>: Failed to establish a new connection: [Errno 111] Connection refused))
Fail to connect to es: Connection error caused by: ConnectionError(Connection error caused by: NewConnectionError(<urllib3.connection.HTTPConnection object at 0x7f5123054a30>: Failed to establish a new connection: [Errno 111] Connection refused))
Fail put f24f491437ce11ef9a420242ac190006/歷代中醫珍本集成醫案十_精校_直_B5_2.0.pdf: S3 operation failed; code: NoSuchKey, message: Object does not exist, resource: /f24f491437ce11ef9a420242ac190006/%E6%AD%B7%E4%BB%A3%E4%B8%AD%E9%86%AB%E7%8F%8D%E6%9C%AC%E9%9B%86%E6%88%90%E9%86%AB%E6%A1%88%E5%8D%81_%E7%B2%BE%E6%A0%A1_%E7%9B%B4_B5_2.0.pdf, request_id: 17DE4A708EF4E2F7, host_id: dd9025bab4ad464b049177c95eb6ebf374d3b3fd1af9251148b658df7ac2e3e8, bucket_name: f24f491437ce11ef9a420242ac190006, object_name: 歷代中醫珍本集成醫案十_精校_直_B5_2.0.pdf
Fail to connect to es: Connection error caused by: ConnectionError(Connection error caused by: NewConnectionError(<urllib3.connection.HTTPConnection object at 0x7f303fb0afe0>: Failed to establish a new connection: [Errno 111] Connection refused))
Fail to connect to es: Connection error caused by: ConnectionError(Connection error caused by: NewConnectionError(<urllib3.connection.HTTPConnection object at 0x7f303fb60fd0>: Failed to establish a new connection: [Errno 111] Connection refused))
Fail to connect to es: Connection error caused by: ConnectionError(Connection error caused by: NewConnectionError(<urllib3.connection.HTTPConnection object at 0x7f303fb62650>: Failed to establish a new connection: [Errno 111] Connection refused))
Fail to connect to es: Connection error caused by: ConnectionError(Connection error caused by: NewConnectionError(<urllib3.connection.HTTPConnection object at 0x7f303fb642b0>: Failed to establish a new connection: [Errno 111] Connection refused))
Fail to connect to es: Connection error caused by: ConnectionError(Connection error caused by: NewConnectionError(<urllib3.connection.HTTPConnection object at 0x7f303fb65750>: Failed to establish a new connection: [Errno 111] Connection refused))
Fail to connect to es: Connection error caused by: ConnectionError(Connection error caused by: NewConnectionError(<urllib3.connection.HTTPConnection object at 0x7f52a8fcaf20>: Failed to establish a new connection: [Errno 111] Connection refused))
Fail to connect to es: Connection error caused by: ConnectionError(Connection error caused by: NewConnectionError(<urllib3.connection.HTTPConnection object at 0x7f75d27f5240>: Failed to establish a new connection: [Errno 111] Connection refused))
Fail to connect to es: Connection error caused by: ConnectionError(Connection error caused by: NewConnectionError(<urllib3.connection.HTTPConnection object at 0x7f52a9020f10>: Failed to establish a new connection: [Errno 111] Connection refused))
Fail to connect to es: Connection error caused by: ConnectionError(Connection error caused by: NewConnectionError(<urllib3.connection.HTTPConnection object at 0x7f75d27f71f0>: Failed to establish a new connection: [Errno 111] Connection refused))
Fail to connect to es: Connection error caused by: ConnectionError(Connection error caused by: NewConnectionError(<urllib3.connection.HTTPConnection object at 0x7f52a9022590>: Failed to establish a new connection: [Errno 111] Connection refused))
Fail to connect to es: Connection error caused by: ConnectionError(Connection error caused by: NewConnectionError(<urllib3.connection.HTTPConnection object at 0x7f75d28288b0>: Failed to establish a new connection: [Errno 111] Connection refused))
Fail to connect to es: Connection error caused by: ConnectionError(Connection error caused by: NewConnectionError(<urllib3.connection.HTTPConnection object at 0x7f52a90301f0>: Failed to establish a new connection: [Errno 111] Connection refused))
Fail to connect to es: Connection error caused by: ConnectionError(Connection error caused by: NewConnectionError(<urllib3.connection.HTTPConnection object at 0x7f75d282a4d0>: Failed to establish a new connection: [Errno 111] Connection refused))
Fail to connect to es: Connection error caused by: ConnectionError(Connection error caused by: NewConnectionError(<urllib3.connection.HTTPConnection object at 0x7f52a9031690>: Failed to establish a new connection: [Errno 111] Connection refused))
Fail to connect to es: Connection error caused by: ConnectionError(Connection error caused by: NewConnectionError(<urllib3.connection.HTTPConnection object at 0x7f75d282b970>: Failed to establish a new connection: [Errno 111] Connection refused))
Fail to connect to es: Connection error caused by: ConnectionError(Connection error caused by: NewConnectionError(<urllib3.connection.HTTPConnection object at 0x7f52a9033490>: Failed to establish a new connection: [Errno 111] Connection refused))
Fail to connect to es: Connection error caused by: ConnectionError(Connection error caused by: NewConnectionError(<urllib3.connection.HTTPConnection object at 0x7f75d283d7b0>: Failed to establish a new connection: [Errno 111] Connection refused))
Fail to connect to es: Connection error caused by: ConnectionError(Connection error caused by: NewConnectionError(<urllib3.connection.HTTPConnection object at 0x7f52a9030970>: Failed to establish a new connection: [Errno 111] Connection refused))
Fail to connect to es: Connection error caused by: ConnectionError(Connection error caused by: NewConnectionError(<urllib3.connection.HTTPConnection object at 0x7f75d283d6c0>: Failed to establish a new connection: [Errno 111] Connection refused))
